Workbook

Sheet README
B2: NFL Quarterback GOAT Model
B3: A multi-model statistical framework for evaluating the greatest quarterbacks in NFL history
B5: Overview | G5: Models Utilized
B6: This project builds a spreadsheet-based analytical model to evaluate and rank the greatest quarterbacks in NFL history. Rather than relying on a single statistic or subjective ranking, the model separates quarterback performance into four distinct analytical dimensions: career greatness, overall performance level, statistical dominance, and postseason performance. Each dimension is evaluated using a separate statistical model built from weighted metrics and normalized statistics. The results are then combined to produce a final GOAT score. Because NFL statistics vary significantly across eras, the analysis uses era-adjusted metrics and relative performance comparisons to allow quarterbacks from different decades to be evaluated on a comparable basis. | G6: Greatest Model
G7: Evaluates legacy and career accomplishments including MVP awards, All-Pro selections, championships, and long-term achievements.
G9: Best Model
G10: Measures overall quarterback performance using efficiency metrics and era-adjusted statistics.
G12: Dominant Model
G13: Analyzes how much quarterbacks separated themselves from league averages during their careers using season-level normalized statistics.
G15: Clutch Model
G16: Examines postseason performance and whether quarterbacks elevated their play relative to regular-season production.
B19: Dataset & Methods | G19: Skills Demonstrated
B20: The analysis evaluates 25 historically significant quarterbacks spanning nearly a century of professional football. | G20: • Spreadsheet modeling and architecture
G21: • Data normalization and statistical standardization
G22: • Weighted scoring systems
G23: • Historical data analysis and era-adjustment methodology
B24: The dataset includes both career statistics and season-level performance data. League averages by season are used to construct era-adjusted statistics and dominance metrics. | G24: • Dashboard-style data presentation and visualizations
G25: • Dynamic data lookups with XLOOKUP, indexing and conditional logic
G26: • Advanced data cleaning and transformation
G27: • Multi-model analytical frameworks and multi-sheet architecture
B28: Several statistical techniques are used throughout the model, including:
B29: • z-score normalization | G29: Future Recommendations
B30: • weighted scoring systems | G30: Future analysis is recommended in the following areas:
B31: • season-level era adjustment | G31: • Incorporation of strength-of-schedule and defense-adjusted value over average (DVOA) scores to better isolate a quarterback's individual impact.
B32: • relative performance comparisons | G32: • As modern or "Next Gen" stats are applied to historical data, additional analysis can be performed to compare advanced stats across eras.
G33: • Apply the weighted model concept (or a similar one) to different positional groups, or different sports entirely.
B34: These methods allow players from very different statistical environments to be evaluated using consistent benchmarks.
B38: Created as a portfolio project demonstrating spreadsheet modeling and sports analytics concepts.
B40: Last Updated: March 7, 2026

Sheet FINAL_GOAT_RANKINGS
B2: # | C2: Quarterback | D2: GOAT SCORES | E2: Greatness Score | F2: Best Score | G2: Dominance Score | H2: Clutch Score | I2: Greatness Rank | J2: Talent Rank | K2: Dominance Rank | L2: Clutch Rank | M2: Average Rank | N2: Rank Spread
B3: 1 | C3: Tom Brady | D3: =sumproduct(E3:H3,Weights_by_Model[[GREATEST]:[CLUTCH]]) -> 76.120608 | E3: {=xlookup(C3,MODEL_GREATEST!B:B,MODEL_GREATEST!C:C)} -> 81.943889 | F3: {=xlookup(C3,MODEL_BEST!B:B,MODEL_BEST!C:C)} -> 71.464861 | G3: {=xlookup(C3,MODEL_DOMINANT!B:B,MODEL_DOMINANT!C:C)} -> 74.866639 | H3: {=xlookup(C3,MODEL_CLUTCH!B:B,MODEL_CLUTCH!C:C)} -> 69.302659 | I3: =rank(E3,E$3:E$27,0) -> 1 | J3: =rank(F3,F$3:F$27,0) -> 2 | K3: =rank(G3,G$3:G$27,0) -> 2 | L3: =rank(H3,H$3:H$27,0) -> 1 | M3: =AVERAGE(I3:L3) -> 1.5 | N3: =MAX(I3:L3)-MIN(I3:L3) -> 1
B4: 2 | C4: Peyton Manning | D4: =sumproduct(E4:H4,Weights_by_Model[[GREATEST]:[CLUTCH]]) -> 70.051835 | E4: {=xlookup(C4,MODEL_GREATEST!B:B,MODEL_GREATEST!C:C)} -> 66.817976 | F4: {=xlookup(C4,MODEL_BEST!B:B,MODEL_BEST!C:C)} -> 77.252893 | G4: {=xlookup(C4,MODEL_DOMINANT!B:B,MODEL_DOMINANT!C:C)} -> 75.570969 | H4: {=xlookup(C4,MODEL_CLUTCH!B:B,MODEL_CLUTCH!C:C)} -> 50.345823 | I4: =rank(E4,E$3:E$27,0) -> 2 | J4: =rank(F4,F$3:F$27,0) -> 1 | K4: =rank(G4,G$3:G$27,0) -> 1 | L4: =rank(H4,H$3:H$27,0) -> 4 | M4: =AVERAGE(I4:L4) -> 2 | N4: =MAX(I4:L4)-MIN(I4:L4) -> 3
B5: 3 | C5: Otto Graham | D5: =sumproduct(E5:H5,Weights_by_Model[[GREATEST]:[CLUTCH]]) -> 56.893872 | E5: {=xlookup(C5,MODEL_GREATEST!B:B,MODEL_GREATEST!C:C)} -> 49.757899 | F5: {=xlookup(C5,MODEL_BEST!B:B,MODEL_BEST!C:C)} -> 63.697301 | G5: {=xlookup(C5,MODEL_DOMINANT!B:B,MODEL_DOMINANT!C:C)} -> 66.953208 | H5: {=xlookup(C5,MODEL_CLUTCH!B:B,MODEL_CLUTCH!C:C)} -> 44.908805 | I5: =rank(E5,E$3:E$27,0) -> 4 | J5: =rank(F5,F$3:F$27,0) -> 3 | K5: =rank(G5,G$3:G$27,0) -> 3 | L5: =rank(H5,H$3:H$27,0) -> 8 | M5: =AVERAGE(I5:L5) -> 4.5 | N5: =MAX(I5:L5)-MIN(I5:L5) -> 5
B6: 4 | C6: Aaron Rodgers | D6: =sumproduct(E6:H6,Weights_by_Model[[GREATEST]:[CLUTCH]]) -> 55.073589 | E6: {=xlookup(C6,MODEL_GREATEST!B:B,MODEL_GREATEST!C:C)} -> 52.882056 | F6: {=xlookup(C6,MODEL_BEST!B:B,MODEL_BEST!C:C)} -> 61.609432 | G6: {=xlookup(C6,MODEL_DOMINANT!B:B,MODEL_DOMINANT!C:C)} -> 55.637675 | H6: {=xlookup(C6,MODEL_CLUTCH!B:B,MODEL_CLUTCH!C:C)} -> 43.104019 | I6: =rank(E6,E$3:E$27,0) -> 3 | J6: =rank(F6,F$3:F$27,0) -> 4 | K6: =rank(G6,G$3:G$27,0) -> 5 | L6: =rank(H6,H$3:H$27,0) -> 9 | M6: =AVERAGE(I6:L6) -> 5.25 | N6: =MAX(I6:L6)-MIN(I6:L6) -> 6
B7: 5 | C7: Patrick Mahomes | D7: =sumproduct(E7:H7,Weights_by_Model[[GREATEST]:[CLUTCH]]) -> 52.053577 | E7: {=xlookup(C7,MODEL_GREATEST!B:B,MODEL_GREATEST!C:C)} -> 44.492196 | F7: {=xlookup(C7,MODEL_BEST!B:B,MODEL_BEST!C:C)} -> 59.080673 | G7: {=xlookup(C7,MODEL_DOMINANT!B:B,MODEL_DOMINANT!C:C)} -> 58.382492 | H7: {=xlookup(C7,MODEL_CLUTCH!B:B,MODEL_CLUTCH!C:C)} -> 48.55998 | I7: =rank(E7,E$3:E$27,0) -> 7 | J7: =rank(F7,F$3:F$27,0) -> 5 | K7: =rank(G7,G$3:G$27,0) -> 4 | L7: =rank(H7,H$3:H$27,0) -> 5 | M7: =AVERAGE(I7:L7) -> 5.25 | N7: =MAX(I7:L7)-MIN(I7:L7) -> 3
B8: 6 | C8: Joe Montana | D8: =sumproduct(E8:H8,Weights_by_Model[[GREATEST]:[CLUTCH]]) -> 50.229486 | E8: {=xlookup(C8,MODEL_GREATEST!B:B,MODEL_GREATEST!C:C)} -> 46.853122 | F8: {=xlookup(C8,MODEL_BEST!B:B,MODEL_BEST!C:C)} -> 51.893139 | G8: {=xlookup(C8,MODEL_DOMINANT!B:B,MODEL_DOMINANT!C:C)} -> 51.366076 | H8: {=xlookup(C8,MODEL_CLUTCH!B:B,MODEL_CLUTCH!C:C)} -> 56.470807 | I8: =rank(E8,E$3:E$27,0) -> 5 | J8: =rank(F8,F$3:F$27,0) -> 9 | K8: =rank(G8,G$3:G$27,0) -> 10 | L8: =rank(H8,H$3:H$27,0) -> 2 | M8: =AVERAGE(I8:L8) -> 6.5 | N8: =MAX(I8:L8)-MIN(I8:L8) -> 8
B9: 7 | C9: Steve Young | D9: =sumproduct(E9:H9,Weights_by_Model[[GREATEST]:[CLUTCH]]) -> 49.72395 | E9: {=xlookup(C9,MODEL_GREATEST!B:B,MODEL_GREATEST!C:C)} -> 42.204584 | F9: {=xlookup(C9,MODEL_BEST!B:B,MODEL_BEST!C:C)} -> 58.264051 | G9: {=xlookup(C9,MODEL_DOMINANT!B:B,MODEL_DOMINANT!C:C)} -> 53.814561 | H9: {=xlookup(C9,MODEL_CLUTCH!B:B,MODEL_CLUTCH!C:C)} -> 45.999887 | I9: =rank(E9,E$3:E$27,0) -> 9 | J9: =rank(F9,F$3:F$27,0) -> 6 | K9: =rank(G9,G$3:G$27,0) -> 6 | L9: =rank(H9,H$3:H$27,0) -> 7 | M9: =AVERAGE(I9:L9) -> 7 | N9: =MAX(I9:L9)-MIN(I9:L9) -> 3
B10: 8 | C10: Drew Brees | D10: =sumproduct(E10:H10,Weights_by_Model[[GREATEST]:[CLUTCH]]) -> 48.943223 | E10: {=xlookup(C10,MODEL_GREATEST!B:B,MODEL_GREATEST!C:C)} -> 46.630254 | F10: {=xlookup(C10,MODEL_BEST!B:B,MODEL_BEST!C:C)} -> 52.380189 | G10: {=xlookup(C10,MODEL_DOMINANT!B:B,MODEL_DOMINANT!C:C)} -> 53.179729 | H10: {=xlookup(C10,MODEL_CLUTCH!B:B,MODEL_CLUTCH!C:C)} -> 39.411194 | I10: =rank(E10,E$3:E$27,0) -> 6 | J10: =rank(F10,F$3:F$27,0) -> 8 | K10: =rank(G10,G$3:G$27,0) -> 7 | L10: =rank(H10,H$3:H$27,0) -> 11 | M10: =AVERAGE(I10:L10) -> 8 | N10: =MAX(I10:L10)-MIN(I10:L10) -> 5
B11: 9 | C11: Dan Marino | D11: =sumproduct(E11:H11,Weights_by_Model[[GREATEST]:[CLUTCH]]) -> 47.332673 | E11: {=xlookup(C11,MODEL_GREATEST!B:B,MODEL_GREATEST!C:C)} -> 41.47069 | F11: {=xlookup(C11,MODEL_BEST!B:B,MODEL_BEST!C:C)} -> 55.531806 | G11: {=xlookup(C11,MODEL_DOMINANT!B:B,MODEL_DOMINANT!C:C)} -> 52.653477 | H11: {=xlookup(C11,MODEL_CLUTCH!B:B,MODEL_CLUTCH!C:C)} -> 35.541596 | I11: =rank(E11,E$3:E$27,0) -> 10 | J11: =rank(F11,F$3:F$27,0) -> 7 | K11: =rank(G11,G$3:G$27,0) -> 8 | L11: =rank(H11,H$3:H$27,0) -> 15 | M11: =AVERAGE(I11:L11) -> 10 | N11: =MAX(I11:L11)-MIN(I11:L11) -> 8
B12: 10 | C12: Sammy Baugh | D12: =sumproduct(E12:H12,Weights_by_Model[[GREATEST]:[CLUTCH]]) -> 43.427741 | E12: {=xlookup(C12,MODEL_GREATEST!B:B,MODEL_GREATEST!C:C)} -> 35.33223 | F12: {=xlookup(C12,MODEL_BEST!B:B,MODEL_BEST!C:C)} -> 48.511876 | G12: {=xlookup(C12,MODEL_DOMINANT!B:B,MODEL_DOMINANT!C:C)} -> 52.308748 | H12: {=xlookup(C12,MODEL_CLUTCH!B:B,MODEL_CLUTCH!C:C)} -> 42.79537 | I12: =rank(E12,E$3:E$27,0) -> 12 | J12: =rank(F12,F$3:F$27,0) -> 10 | K12: =rank(G12,G$3:G$27,0) -> 9 | L12: =rank(H12,H$3:H$27,0) -> 10 | M12: =AVERAGE(I12:L12) -> 10.25 | N12: =MAX(I12:L12)-MIN(I12:L12) -> 3
B13: 11 | C13: Brett Favre | D13: =sumproduct(E13:H13,Weights_by_Model[[GREATEST]:[CLUTCH]]) -> 42.600071 | E13: {=xlookup(C13,MODEL_GREATEST!B:B,MODEL_GREATEST!C:C)} -> 42.772917 | F13: {=xlookup(C13,MODEL_BEST!B:B,MODEL_BEST!C:C)} -> 42.516221 | G13: {=xlookup(C13,MODEL_DOMINANT!B:B,MODEL_DOMINANT!C:C)} -> 45.756804 | H13: {=xlookup(C13,MODEL_CLUTCH!B:B,MODEL_CLUTCH!C:C)} -> 35.846768 | I13: =rank(E13,E$3:E$27,0) -> 8 | J13: =rank(F13,F$3:F$27,0) -> 12 | K13: =rank(G13,G$3:G$27,0) -> 13 | L13: =rank(H13,H$3:H$27,0) -> 14 | M13: =AVERAGE(I13:L13) -> 11.75 | N13: =MAX(I13:L13)-MIN(I13:L13) -> 6
B14: 12 | C14: Johnny Unitas | D14: =sumproduct(E14:H14,Weights_by_Model[[GREATEST]:[CLUTCH]]) -> 39.878845 | E14: {=xlookup(C14,MODEL_GREATEST!B:B,MODEL_GREATEST!C:C)} -> 37.796774 | F14: {=xlookup(C14,MODEL_BEST!B:B,MODEL_BEST!C:C)} -> 41.713909 | G14: {=xlookup(C14,MODEL_DOMINANT!B:B,MODEL_DOMINANT!C:C)} -> 45.988036 | H14: {=xlookup(C14,MODEL_CLUTCH!B:B,MODEL_CLUTCH!C:C)} -> 30.483552 | I14: =rank(E14,E$3:E$27,0) -> 11 | J14: =rank(F14,F$3:F$27,0) -> 13 | K14: =rank(G14,G$3:G$27,0) -> 12 | L14: =rank(H14,H$3:H$27,0) -> 19 | M14: =AVERAGE(I14:L14) -> 13.75 | N14: =MAX(I14:L14)-MIN(I14:L14) -> 8
... B27: 25 | C27: YA Tittle | D27: =sumproduct(E27:H27,Weights_by_Model[[GREATEST]:[CLUTCH]]) -> 20.460328 | E27: {=xlookup(C27,MODEL_GREATEST!B:B,MODEL_GREATEST!C:C)} -> 16.278935 | F27: {=xlookup(C27,MODEL_BEST!B:B,MODEL_BEST!C:C)} -> 23.470475 | G27: {=xlookup(C27,MODEL_DOMINANT!B:B,MODEL_DOMINANT!C:C)} -> 26.680099 | H27: {=xlookup(C27,MODEL_CLUTCH!B:B,MODEL_CLUTCH!C:C)} -> 15.715918 | I27: =rank(E27,E$3:E$27,0) -> 25 | J27: =rank(F27,F$3:F$27,0) -> 24 | K27: =rank(G27,G$3:G$27,0) -> 23 | L27: =rank(H27,H$3:H$27,0) -> 25 | M27: =AVERAGE(I27:L27) -> 24.25 | N27: =MAX(I27:L27)-MIN(I27:L27) -> 2

Sheet DASHBOARD
B2: NFL Quarterback GOAT Model Dashboard
B3: Comparative rankings of 25 quarterbacks across four analytical models
B5: Quarterback Selector
B6: Tom Brady
C7: SCORE | D7: RANK | F7: Model | G7: Score
B8: GOAT SCORE | C8: {=xlookup(B6,FINAL_GOAT_RANKINGS!C:C,FINAL_GOAT_RANKINGS!D:D,0)} -> 76.120608 | D8: {=xlookup(B6,FINAL_GOAT_RANKINGS!C:C,FINAL_GOAT_RANKINGS!B:B,0)} -> 1 | F8: Greatest | G8: =C9 -> 81.943889
B9: Greatest | C9: {=xlookup(B6,FINAL_GOAT_RANKINGS!C:C,FINAL_GOAT_RANKINGS!E:E,0)} -> 81.943889 | D9: {=xlookup(B6,FINAL_GOAT_RANKINGS!C:C,FINAL_GOAT_RANKINGS!I:I,0)} -> 1 | F9: Best | G9: =C10 -> 71.464861
B10: Best | C10: {=xlookup(B6,FINAL_GOAT_RANKINGS!C:C,FINAL_GOAT_RANKINGS!F:F,0)} -> 71.464861 | D10: {=xlookup(B6,FINAL_GOAT_RANKINGS!C:C,FINAL_GOAT_RANKINGS!J:J,0)} -> 2 | F10: Dominant | G10: =C11 -> 74.866639
B11: Dominant | C11: {=xlookup(B6,FINAL_GOAT_RANKINGS!C:C,FINAL_GOAT_RANKINGS!G:G,0)} -> 74.866639 | D11: {=xlookup(B6,FINAL_GOAT_RANKINGS!C:C,FINAL_GOAT_RANKINGS!K:K,0)} -> 2 | F11: Clutch | G11: =C12 -> 69.302659
B12: Clutch | C12: {=xlookup(B6,FINAL_GOAT_RANKINGS!C:C,FINAL_GOAT_RANKINGS!H:H,0)} -> 69.302659 | D12: {=xlookup(B6,FINAL_GOAT_RANKINGS!C:C,FINAL_GOAT_RANKINGS!L:L,0)} -> 1
B15: Final GOAT Rankings
B17: Rank | C17: QB | D17: GOAT Score | E17: Greatest | F17: Best | G17: Dominant | H17: Clutch
B18: =FINAL_GOAT_RANKINGS!B3 -> 1 | C18: =FINAL_GOAT_RANKINGS!C3 -> Tom Brady | D18: =FINAL_GOAT_RANKINGS!D3 -> 76.120608 | E18: =FINAL_GOAT_RANKINGS!E3 -> 81.943889 | F18: =FINAL_GOAT_RANKINGS!F3 -> 71.464861 | G18: =FINAL_GOAT_RANKINGS!G3 -> 74.866639 | H18: =FINAL_GOAT_RANKINGS!H3 -> 69.302659
B19: =FINAL_GOAT_RANKINGS!B4 -> 2 | C19: =FINAL_GOAT_RANKINGS!C4 -> Peyton Manning | D19: =FINAL_GOAT_RANKINGS!D4 -> 70.051835 | E19: =FINAL_GOAT_RANKINGS!E4 -> 66.817976 | F19: =FINAL_GOAT_RANKINGS!F4 -> 77.252893 | G19: =FINAL_GOAT_RANKINGS!G4 -> 75.570969 | H19: =FINAL_GOAT_RANKINGS!H4 -> 50.345823
B20: =FINAL_GOAT_RANKINGS!B5 -> 3 | C20: =FINAL_GOAT_RANKINGS!C5 -> Otto Graham | D20: =FINAL_GOAT_RANKINGS!D5 -> 56.893872 | E20: =FINAL_GOAT_RANKINGS!E5 -> 49.757899 | F20: =FINAL_GOAT_RANKINGS!F5 -> 63.697301 | G20: =FINAL_GOAT_RANKINGS!G5 -> 66.953208 | H20: =FINAL_GOAT_RANKINGS!H5 -> 44.908805
B21: =FINAL_GOAT_RANKINGS!B6 -> 4 | C21: =FINAL_GOAT_RANKINGS!C6 -> Aaron Rodgers | D21: =FINAL_GOAT_RANKINGS!D6 -> 55.073589 | E21: =FINAL_GOAT_RANKINGS!E6 -> 52.882056 | F21: =FINAL_GOAT_RANKINGS!F6 -> 61.609432 | G21: =FINAL_GOAT_RANKINGS!G6 -> 55.637675 | H21: =FINAL_GOAT_RANKINGS!H6 -> 43.104019
B22: =FINAL_GOAT_RANKINGS!B7 -> 5 | C22: =FINAL_GOAT_RANKINGS!C7 -> Patrick Mahomes | D22: =FINAL_GOAT_RANKINGS!D7 -> 52.053577 | E22: =FINAL_GOAT_RANKINGS!E7 -> 44.492196 | F22: =FINAL_GOAT_RANKINGS!F7 -> 59.080673 | G22: =FINAL_GOAT_RANKINGS!G7 -> 58.382492 | H22: =FINAL_GOAT_RANKINGS!H7 -> 48.55998
B23: =FINAL_GOAT_RANKINGS!B8 -> 6 | C23: =FINAL_GOAT_RANKINGS!C8 -> Joe Montana | D23: =FINAL_GOAT_RANKINGS!D8 -> 50.229486 | E23: =FINAL_GOAT_RANKINGS!E8 -> 46.853122 | F23: =FINAL_GOAT_RANKINGS!F8 -> 51.893139 | G23: =FINAL_GOAT_RANKINGS!G8 -> 51.366076 | H23: =FINAL_GOAT_RANKINGS!H8 -> 56.470807
B24: =FINAL_GOAT_RANKINGS!B9 -> 7 | C24: =FINAL_GOAT_RANKINGS!C9 -> Steve Young | D24: =FINAL_GOAT_RANKINGS!D9 -> 49.72395 | E24: =FINAL_GOAT_RANKINGS!E9 -> 42.204584 | F24: =FINAL_GOAT_RANKINGS!F9 -> 58.264051 | G24: =FINAL_GOAT_RANKINGS!G9 -> 53.814561 | H24: =FINAL_GOAT_RANKINGS!H9 -> 45.999887
B25: =FINAL_GOAT_RANKINGS!B10 -> 8 | C25: =FINAL_GOAT_RANKINGS!C10 -> Drew Brees | D25: =FINAL_GOAT_RANKINGS!D10 -> 48.943223 | E25: =FINAL_GOAT_RANKINGS!E10 -> 46.630254 | F25: =FINAL_GOAT_RANKINGS!F10 -> 52.380189 | G25: =FINAL_GOAT_RANKINGS!G10 -> 53.179729 | H25: =FINAL_GOAT_RANKINGS!H10 -> 39.411194
B26: =FINAL_GOAT_RANKINGS!B11 -> 9 | C26: =FINAL_GOAT_RANKINGS!C11 -> Dan Marino | D26: =FINAL_GOAT_RANKINGS!D11 -> 47.332673 | E26: =FINAL_GOAT_RANKINGS!E11 -> 41.47069 | F26: =FINAL_GOAT_RANKINGS!F11 -> 55.531806 | G26: =FINAL_GOAT_RANKINGS!G11 -> 52.653477 | H26: =FINAL_GOAT_RANKINGS!H11 -> 35.541596
B27: =FINAL_GOAT_RANKINGS!B12 -> 10 | C27: =FINAL_GOAT_RANKINGS!C12 -> Sammy Baugh | D27: =FINAL_GOAT_RANKINGS!D12 -> 43.427741 | E27: =FINAL_GOAT_RANKINGS!E12 -> 35.33223 | F27: =FINAL_GOAT_RANKINGS!F12 -> 48.511876 | G27: =FINAL_GOAT_RANKINGS!G12 -> 52.308748 | H27: =FINAL_GOAT_RANKINGS!H12 -> 42.79537
B28: =FINAL_GOAT_RANKINGS!B13 -> 11 | C28: =FINAL_GOAT_RANKINGS!C13 -> Brett Favre | D28: =FINAL_GOAT_RANKINGS!D13 -> 42.600071 | E28: =FINAL_GOAT_RANKINGS!E13 -> 42.772917 | F28: =FINAL_GOAT_RANKINGS!F13 -> 42.516221 | G28: =FINAL_GOAT_RANKINGS!G13 -> 45.756804 | H28: =FINAL_GOAT_RANKINGS!H13 -> 35.846768
B29: =FINAL_GOAT_RANKINGS!B14 -> 12 | C29: =FINAL_GOAT_RANKINGS!C14 -> Johnny Unitas | D29: =FINAL_GOAT_RANKINGS!D14 -> 39.878845 | E29: =FINAL_GOAT_RANKINGS!E14 -> 37.796774 | F29: =FINAL_GOAT_RANKINGS!F14 -> 41.713909 | G29: =FINAL_GOAT_RANKINGS!G14 -> 45.988036 | H29: =FINAL_GOAT_RANKINGS!H14 -> 30.483552
... B42: =FINAL_GOAT_RANKINGS!B27 -> 25 | C42: =FINAL_GOAT_RANKINGS!C27 -> YA Tittle | D42: =FINAL_GOAT_RANKINGS!D27 -> 20.460328 | E42: =FINAL_GOAT_RANKINGS!E27 -> 16.278935 | F42: =FINAL_GOAT_RANKINGS!F27 -> 23.470475 | G42: =FINAL_GOAT_RANKINGS!G27 -> 26.680099 | H42: =FINAL_GOAT_RANKINGS!H27 -> 15.715918

Sheet QB_ROSTER
B2: # | C2: Name | D2: Born | E2: Birthplace | F2: College | G2: Draft | H2: Career Start | I2: Career End | J2: Team(s)
B3: 33 | C3: Sammy Baugh | D3: 5190 | E3: Temple, TX | F3: TCU | G3: 46028 | H3: 1937 | I3: 1952 | J3: WAS
B4: 12 | C4: Terry Bradshaw | D4: 17778 | E4: Shreveport, LA | F4: Louisiana Tech | G4: 46023 | H4: 1970 | I4: 1983 | J4: PIT
B5: 12 | C5: Tom Brady | D5: 28340 | E5: San Mateo, CA | F5: Michigan | G5: 6-199 | H5: 2000 | I5: 2022 | J5: NWE, TAM
B6: 9 | C6: Drew Brees | D6: 28870 | E6: Austin, TX | F6: Purdue | G6: 2-32 | H6: 2001 | I6: 2020 | J6: SDG, NOR
B7: 7 | C7: John Elway | D7: 22095 | E7: Port Angeles, WA | F7: Stanford | G7: 46023 | H7: 1983 | I7: 1998 | J7: DEN
B8: 4 | C8: Brett Favre | D8: 25486 | E8: Gulfport, MS | F8: Southern Miss | G8: 2-33 | H8: 1991 | I8: 2010 | J8: ATL, GNB, NYJ, MIN
B9: 14 | C9: Dan Fouts | D9: 18789 | E9: San Francisco, CA | F9: Oregon | G9: 3-64 | H9: 1973 | I9: 1987 | J9: SDG
B10: 14 | C10: Otto Graham | D10: 8011 | E10: Waukegan, IL | F10: Northwestern | G10: 46026 | H10: 1946 | I10: 1955 | J10: CLE
B11: 8 | C11: Lamar Jackson | D11: 35437 | E11: Pompano Beach, FL | F11: Louisville | G11: 1-32 | H11: 2018 | I11: Active | J11: BAL
B12: 12 | C12: Jim Kelly | D12: 21960 | E12: Pittsburgh, PA | F12: Miami | G12: 46036 | H12: 1986 | I12: 1996 | J12: BUF
B13: 15 | C13: Patrick Mahomes | D13: 34959 | E13: Tyler, TX | F13: Texas Tech | G13: 46032 | H13: 2017 | I13: Active | J13: KAN
B14: 18 | C14: Peyton Manning | D14: 27843 | E14: New Orleans, LA | F14: Tennessee | G14: 46023 | H14: 1998 | I14: 2015 | J14: IND, DEN
B15: 13 | C15: Dan Marino | D15: 22539 | E15: Pittsburgh, PA | F15: Pittsburgh | G15: 46049 | H15: 1983 | I15: 1999 | J15: MIA
B16: 16 | C16: Joe Montana | D16: 20617 | E16: New Eagle, PA | F16: Notre Dame | G16: 3-82 | H16: 1979 | I16: 1994 | J16: SFO, KAN
B17: 1 | C17: Warren Moon | D17: 20777 | E17: Los Angeles, CA | F17: Washington | G17: Undrafted | H17: 1984 | I17: 2000 | J17: HOU, MIN, SEA, KAN
B18: 12 | C18: Aaron Rodgers | D18: 30349 | E18: Chico, CA | F18: California | G18: 46046 | H18: 2005 | I18: Active | J18: GNB, NYJ, PIT
B19: 7 | C19: Ben Roethlisberger | D19: 30012 | E19: Lima, OH | F19: Miami (OH) | G19: 46033 | H19: 2004 | I19: 2021 | J19: PIT
B20: 12 | C20: Ken Stabler | D20: 16796 | E20: Foley, AL | F20: Alabama | G20: 2-52 | H20: 1970 | I20: 1984 | J20: OAK, HOU, NOR
B21: 15 | C21: Bart Starr | D21: 12428 | E21: Montgomery, AL | F21: Alabama | G21: 17-200 | H21: 1956 | I21: 1971 | J21: GNB
B22: 12 | C22: Roger Staubach | D22: 15377 | E22: Cincinnati, OH | F22: Navy | G22: 10-129 | H22: 1969 | I22: 1979 | J22: DAL
B23: 10 | C23: Fran Tarkenton | D23: 14644 | E23: Richmond, VA | F23: Georgia | G23: 46110 | H23: 1961 | I23: 1978 | J23: MIN, NYG
B24: 14 | C24: Y.A. Tittle | D24: 9794 | E24: Marshall, TX | F24: LSU | G24: 46028 | H24: 1948 | I24: 1964 | J24: BCL, SFO, NYG
B25: 19 | C25: Johnny Unitas | D25: 12181 | E25: Pittsburgh, PA | F25: Louisville | G25: 9-102 | H25: 1956 | I25: 1973 | J25: BAL, SDG
B26: 13 | C26: Kurt Warner | D26: 26106 | E26: Burlington, IA | F26: Northern Iowa | G26: Undrafted | H26: 1998 | I26: 2009 | J26: STL, NYG, ARI
B27: 8 | C27: Steve Young | D27: 22565 | E27: Salt Lake City, UT | F27: BYU | G27: 46023 | H27: 1985 | I27: 1999 | J27: TAM, SFO
B29: HONORABLE MENTIONS
B30: Historical
B31: Sid Luckman
B32: Norm Van Brocklin
B33: Sonny Jurgensen
B34: Len Dawson
B35: George Blanda
B36: Golden Era
B37: Joe Namath
B38: Ken Anderson
B39: Boomer Esiason
B40: Joe Theismann
... B47: Russell Wilson

Sheet CATEGORY_DEFINITIONS
C2: Category | D2: Definition | E2: Rationale
B3: Team Success | C3: Super Bowl Wins | D3: Total number of Super Bowls won as a starter (includes NFL Championships from pre-Super Bowl era) | E3: The highest measure of team success, generally used as a starting point for "greatness" talks. Weighted highly for Greatness and Clutch models.
C4: Playoff Success Score | D4: Defined as {(1 * # Conference Championship Wins) + (0.5 * # Divisional Round Wins) + (0.25 * # Wild Card Round Wins)} | E4: Adds value for playoff success outside of just the Super Bowl. Helps prevent quarterbacks from being punished too harshly for never winning a ring.
B5: Individual Accolades | C5: Super Bowl MVPs | D5: Total number of Super Bowl MVPs won | E5: Isolates individual impact on the game’s biggest stage. While championships are team-based, the MVP award identifies the primary engine of a title run and serves as a definitive marker of "Big Game" legacy.
C6: MVP Shares | D6: Total share of MVP votes across their career, defined as {Actual Points Received / Maximum Possible Points} | E6: The highest individual honor in football. Shares are used as opposed to total number of MVPs to avoid an all-or-nothing metric that would punish quarterbacks for placing highly but not winning.
C7: All Pro Score | D7: Defined as {(# First Team All-Pros) + (0.5 * # Second Team All-Pros)} | E7: The gold standard for measuring peer dominance. Unlike popularity-based awards, All-Pro honors signify "best-in-class" status. This weighted metric rewards seasons where the QB was the best in the league.
C8: Pro Bowls | D8: Total amount of Pro Bowls in their career | E8: A measure of season-by-season excellence. High counts indicate a long window of elite performance, serving as a "longevity floor" to verify a QB remained a top-tier asset for the majority of their career. Weighted lower due to the Pro Bowl's recent reputation as a popularity contest.
B9: Career Statistics | C9: Yards* | D9: Total career passing yards | E9: One of the main quarterback statistics. While not the only measure of what makes a great QB, it is always relevant and frequently used when debating the greats. Different models utilize different measures of "yards", including overall volume, per-season totals, and adjusted totals.
C10: Touchdowns* | D10: Total career passing touchdowns | E10: Similar to yards, one of the most commonly cited measures of quarterback success. Scoring more points is the best way to win, after all. Also utilizes different metrics for each model.
C11: Career ANY/A+ | D11: Total career ANY/A+ value | E11: Adjusted net yards per pass attempt, adjusted for era. A common metric used to evaluate quarterback efficiency, utilized here as a generalist stat to compare overall QB performance. Also forms the basis for Peak and Dominance scores.
C12: Rush Yards per Game | D12: Average rush yards per game across entire career | E12: Measures a quarterback's "dual-threat" capability and impact as a floor-raiser. High rushing volume forces defensive adjustments and creates efficiency in the passing game, rewarding QBs who added significant value through non-traditional yardage and modern playmaking.
C13: Negative Play Rate | D13: Defined as {(2/3 * Int%+) + (1/3 * Sack%+)} | E13: Evaluates poise and risk management by tracking drive-killing outcomes. Combining Sack and INT rates penalizes "stat-padders" who take sacks to preserve completion percentages, favoring those who efficiently move the chains.
B14: "Greatness" Calculations | C14: Peak Score | D14: Calculated as the highest average ANY/A+ value across 5 consecutive seasons during the course of their career | E14: Measures a quarterback's absolute "ceiling" rather than just career accumulation. By isolating their best consecutive seasons, this metric identifies generational peaks and prevents "compilers" from outranking more dominant, shorter-lived primes.
C15: Dominance Score | D15: How many seasons ranking top 3 in ANY/A | E15: Measures how far a quarterback "lapped the field" compared to his contemporaries. By using z-score normalization against league-average benchmarks, this metric identifies players who transcended their era’s statistical environment, ensuring historical dominance isn't erased by modern passing inflation.
C16: Playoff Elevation Score | D16: Defined as {Career Playoff ANY/A / Career Regular Season ANY/A} | E16: Evaluates whether a quarterback improved or regressed when the stakes increased. This metric compares a player's postseason efficiency (ANY/A) directly against their own regular-season career averages. It identifies "force multipliers" who consistently raised their level of play in the playoffs.
C17: *varies by model
B19: Disclaimers:
B20: For years where ANY/A+ data is unavailable, an aggregate of 2/3 AY/A+ and 1/3 Rate+ will be used.
B21: For years where sack data is unavailable, estimations are made using career averages, season averages, and qualitative anecdotal evidence and reports.
B22: For years where sack data is unavailable or limited, reported voting is used to estimate the equivalent "share" of modern MVP awards.
B24: Note on use of ANY/A+:
B25: While ANY/A+ is a popularly used metric for evaluating overall quarterback efficiency, and is beneficial for era-comparisons, some may criticize it for not accounting for certain relevant factors (first downs, air yards, dropped passes, etc.) and opt for a more well-rounded metric: EPA+, or expected points added (adjusted). However, historical records of both EPA counts as well as the individual statistics that factor into its calculation are too limited to be reliably used across eras. The calculations would rely on too many estimates to be a truly accurate model to compare quarterbacks.

Sheet CATEGORY_WEIGHTS
B2: GREATEST | C2: BEST | D2: DOMINANT | E2: CLUTCH
B3: What makes a QB great? Values lifetime achievements, "classic" statistics, and overall success. | C3: Prioritized individual ability over team and playoff success. The "raw talent" argument. | D3: Favors era-adjusted stats in an attempt to display how much better a given QB was than his peers. | E3: Which QBs perform best when the lights are brightest? Places higher weights on playoff and Super Bowl success.
B4: Tier 1 (6%)
B5: Super Bowl Wins | C5: Peak Score | D5: Dominance Score | E5: Super Bowl MVPs
E6: Playoff Elevation Score
B7: Tier 2 (4.5%)
B8: MVP Shares | C8: Career ANY/A+ | D8: Yards* | E8: Super Bowl Wins
B9: Yards* | C9: Dominance Score | D9: Touchdowns* | E9: Playoff Success Score
B10: Touchdowns* | C10: MVP Shares | D10: Career ANY/A+ | E10: Yards*
B11: Peak Score | E11: Touchdowns*
B13: Tier 3 (3%)
B14: Super Bowl MVPs | C14: Yards* | D14: Super Bowl Wins | E14: All Pro Score
B15: Playoff Success Score | C15: Touchdowns* | D15: Super Bowl MVPs | E15: Peak Score
B16: All Pro Score | C16: All Pro Score | D16: MVP Shares | E16: Dominance Score
B17: Playoff Elevation Score | C17: Negative Play Rate | D17: All Pro Score
B18: Dominance Score | D18: Peak Score
B20: Tier 4 (1.8%)
B21: Career ANY/A+ | C21: Super Bowl MVPs | D21: Playoff Success Score | E21: MVP Shares
B22: Negative Play Rate | C22: Playoff Elevation Score | D22: Playoff Elevation Score | E22: Career ANY/A+
C23: Rush Yards per Game | D23: Negative Play Rate | E23: Negative Play Rate
B26: Tier 5 (1%)
B27: Pro Bowls | C27: Pro Bowls | D27: Pro Bowls | E27: Pro Bowls
B28: Rush Yards per Game | C28: Super Bowl Wins | D28: Rush Yards per Game | E28: Rush Yards per Game
C29: Playoff Success Score
B32: Total Yards | C32: Yards per Season | D32: Adjusted Yards per Season | E32: Playoff YPG
B33: Total Touchdowns | C33: TDs per Season | D33: Adjusted TDs per Season | E33: Playoff TDPG

Sheet TIER_WEIGHTS
A1: Category | B1: GREATEST | C1: BEST | D1: DOMINANT | E1: CLUTCH
A2: Super Bowl Wins | B2: =IFS( ISNUMBER(MATCH($A2, CATEGORY_WEIGHTS!B$5:B$6, 0)), 0.06, ISNUMBER(MATCH($A2, CATEGORY_WEIGHTS!B$8:B$12, 0)), 0.045, ISNUMBER(MATCH($A2, CATEGORY_WEIGHTS!B$14:B$19, 0)), 0.03, ISNUMBER(MATCH($A2, CATEGORY_WEIGHTS!B$21:B$25, 0)), 0.018, ISNUMBER(MATCH($A2, CATEGORY_WEIGHTS!B$27:B$30, 0)), 0.01 ) -> 0.06 | C2: =IFS( ISNUMBER(MATCH($A2, CATEGORY_WEIGHTS!C$5:C$6, 0)), 0.06, ISNUMBER(MATCH($A2, CATEGORY_WEIGHTS!C$8:C$12, 0)), 0.045, ISNUMBER(MATCH($A2, CATEGORY_WEIGHTS!C$14:C$19, 0)), 0.03, ISNUMBER(MATCH($A2, CATEGORY_WEIGHTS!C$21:C$25, 0)), 0.018, ISNUMBER(MATCH($A2, CATEGORY_WEIGHTS!C$27:C$30, 0)), 0.01 ) -> 0.01 | D2: =IFS( ISNUMBER(MATCH($A2, CATEGORY_WEIGHTS!D$5:D$6, 0)), 0.06, ISNUMBER(MATCH($A2, CATEGORY_WEIGHTS!D$8:D$12, 0)), 0.045, ISNUMBER(MATCH($A2, CATEGORY_WEIGHTS!D$14:D$19, 0)), 0.03, ISNUMBER(MATCH($A2, CATEGORY_WEIGHTS!D$21:D$25, 0)), 0.018, ISNUMBER(MATCH($A2, CATEGORY_WEIGHTS!D$27:D$30, 0)), 0.01 ) -> 0.03 | E2: =IFS( ISNUMBER(MATCH($A2, CATEGORY_WEIGHTS!E$5:E$6, 0)), 0.06, ISNUMBER(MATCH($A2, CATEGORY_WEIGHTS!E$8:E$12, 0)), 0.045, ISNUMBER(MATCH($A2, CATEGORY_WEIGHTS!E$14:E$19, 0)), 0.03, ISNUMBER(MATCH($A2, CATEGORY_WEIGHTS!E$21:E$25, 0)), 0.018, ISNUMBER(MATCH($A2, CATEGORY_WEIGHTS!E$27:E$30, 0)), 0.01 ) -> 0.045
A3: MVP Shares | B3: =IFS( ISNUMBER(MATCH($A3, CATEGORY_WEIGHTS!B$5:B$6, 0)), 0.06, ISNUMBER(MATCH($A3, CATEGORY_WEIGHTS!B$8:B$12, 0)), 0.045, ISNUMBER(MATCH($A3, CATEGORY_WEIGHTS!B$14:B$19, 0)), 0.03, ISNUMBER(MATCH($A3, CATEGORY_WEIGHTS!B$21:B$25, 0)), 0.018, ISNUMBER(MATCH($A3, CATEGORY_WEIGHTS!B$27:B$30, 0)), 0.01 ) -> 0.045 | C3: =IFS( ISNUMBER(MATCH($A3, CATEGORY_WEIGHTS!C$5:C$6, 0)), 0.06, ISNUMBER(MATCH($A3, CATEGORY_WEIGHTS!C$8:C$12, 0)), 0.045, ISNUMBER(MATCH($A3, CATEGORY_WEIGHTS!C$14:C$19, 0)), 0.03, ISNUMBER(MATCH($A3, CATEGORY_WEIGHTS!C$21:C$25, 0)), 0.018, ISNUMBER(MATCH($A3, CATEGORY_WEIGHTS!C$27:C$30, 0)), 0.01 ) -> 0.045 | D3: =IFS( ISNUMBER(MATCH($A3, CATEGORY_WEIGHTS!D$5:D$6, 0)), 0.06, ISNUMBER(MATCH($A3, CATEGORY_WEIGHTS!D$8:D$12, 0)), 0.045, ISNUMBER(MATCH($A3, CATEGORY_WEIGHTS!D$14:D$19, 0)), 0.03, ISNUMBER(MATCH($A3, CATEGORY_WEIGHTS!D$21:D$25, 0)), 0.018, ISNUMBER(MATCH($A3, CATEGORY_WEIGHTS!D$27:D$30, 0)), 0.01 ) -> 0.03 | E3: =IFS( ISNUMBER(MATCH($A3, CATEGORY_WEIGHTS!E$5:E$6, 0)), 0.06, ISNUMBER(MATCH($A3, CATEGORY_WEIGHTS!E$8:E$12, 0)), 0.045, ISNUMBER(MATCH($A3, CATEGORY_WEIGHTS!E$14:E$19, 0)), 0.03, ISNUMBER(MATCH($A3, CATEGORY_WEIGHTS!E$21:E$25, 0)), 0.018, ISNUMBER(MATCH($A3, CATEGORY_WEIGHTS!E$27:E$30, 0)), 0.01 ) -> 0.018 | G3: Model | H3: GREATEST | I3: BEST | J3: DOMINANT | K3: CLUTCH
A4: Yards* | B4: =IFS( ISNUMBER(MATCH($A4, CATEGORY_WEIGHTS!B$5:B$6, 0)), 0.06, ISNUMBER(MATCH($A4, CATEGORY_WEIGHTS!B$8:B$12, 0)), 0.045, ISNUMBER(MATCH($A4, CATEGORY_WEIGHTS!B$14:B$19, 0)), 0.03, ISNUMBER(MATCH($A4, CATEGORY_WEIGHTS!B$21:B$25, 0)), 0.018, ISNUMBER(MATCH($A4, CATEGORY_WEIGHTS!B$27:B$30, 0)), 0.01 ) -> 0.045 | C4: =IFS( ISNUMBER(MATCH($A4, CATEGORY_WEIGHTS!C$5:C$6, 0)), 0.06, ISNUMBER(MATCH($A4, CATEGORY_WEIGHTS!C$8:C$12, 0)), 0.045, ISNUMBER(MATCH($A4, CATEGORY_WEIGHTS!C$14:C$19, 0)), 0.03, ISNUMBER(MATCH($A4, CATEGORY_WEIGHTS!C$21:C$25, 0)), 0.018, ISNUMBER(MATCH($A4, CATEGORY_WEIGHTS!C$27:C$30, 0)), 0.01 ) -> 0.03 | D4: =IFS( ISNUMBER(MATCH($A4, CATEGORY_WEIGHTS!D$5:D$6, 0)), 0.06, ISNUMBER(MATCH($A4, CATEGORY_WEIGHTS!D$8:D$12, 0)), 0.045, ISNUMBER(MATCH($A4, CATEGORY_WEIGHTS!D$14:D$19, 0)), 0.03, ISNUMBER(MATCH($A4, CATEGORY_WEIGHTS!D$21:D$25, 0)), 0.018, ISNUMBER(MATCH($A4, CATEGORY_WEIGHTS!D$27:D$30, 0)), 0.01 ) -> 0.045 | E4: =IFS( ISNUMBER(MATCH($A4, CATEGORY_WEIGHTS!E$5:E$6, 0)), 0.06, ISNUMBER(MATCH($A4, CATEGORY_WEIGHTS!E$8:E$12, 0)), 0.045, ISNUMBER(MATCH($A4, CATEGORY_WEIGHTS!E$14:E$19, 0)), 0.03, ISNUMBER(MATCH($A4, CATEGORY_WEIGHTS!E$21:E$25, 0)), 0.018, ISNUMBER(MATCH($A4, CATEGORY_WEIGHTS!E$27:E$30, 0)), 0.01 ) -> 0.045 | G4: Weight | H4: 0.4 | I4: 0.3 | J4: 0.2 | K4: 0.1
A5: Touchdowns* | B5: =IFS( ISNUMBER(MATCH($A5, CATEGORY_WEIGHTS!B$5:B$6, 0)), 0.06, ISNUMBER(MATCH($A5, CATEGORY_WEIGHTS!B$8:B$12, 0)), 0.045, ISNUMBER(MATCH($A5, CATEGORY_WEIGHTS!B$14:B$19, 0)), 0.03, ISNUMBER(MATCH($A5, CATEGORY_WEIGHTS!B$21:B$25, 0)), 0.018, ISNUMBER(MATCH($A5, CATEGORY_WEIGHTS!B$27:B$30, 0)), 0.01 ) -> 0.045 | C5: =IFS( ISNUMBER(MATCH($A5, CATEGORY_WEIGHTS!C$5:C$6, 0)), 0.06, ISNUMBER(MATCH($A5, CATEGORY_WEIGHTS!C$8:C$12, 0)), 0.045, ISNUMBER(MATCH($A5, CATEGORY_WEIGHTS!C$14:C$19, 0)), 0.03, ISNUMBER(MATCH($A5, CATEGORY_WEIGHTS!C$21:C$25, 0)), 0.018, ISNUMBER(MATCH($A5, CATEGORY_WEIGHTS!C$27:C$30, 0)), 0.01 ) -> 0.03 | D5: =IFS( ISNUMBER(MATCH($A5, CATEGORY_WEIGHTS!D$5:D$6, 0)), 0.06, ISNUMBER(MATCH($A5, CATEGORY_WEIGHTS!D$8:D$12, 0)), 0.045, ISNUMBER(MATCH($A5, CATEGORY_WEIGHTS!D$14:D$19, 0)), 0.03, ISNUMBER(MATCH($A5, CATEGORY_WEIGHTS!D$21:D$25, 0)), 0.018, ISNUMBER(MATCH($A5, CATEGORY_WEIGHTS!D$27:D$30, 0)), 0.01 ) -> 0.045 | E5: =IFS( ISNUMBER(MATCH($A5, CATEGORY_WEIGHTS!E$5:E$6, 0)), 0.06, ISNUMBER(MATCH($A5, CATEGORY_WEIGHTS!E$8:E$12, 0)), 0.045, ISNUMBER(MATCH($A5, CATEGORY_WEIGHTS!E$14:E$19, 0)), 0.03, ISNUMBER(MATCH($A5, CATEGORY_WEIGHTS!E$21:E$25, 0)), 0.018, ISNUMBER(MATCH($A5, CATEGORY_WEIGHTS!E$27:E$30, 0)), 0.01 ) -> 0.045
A6: Peak Score | B6: =IFS( ISNUMBER(MATCH($A6, CATEGORY_WEIGHTS!B$5:B$6, 0)), 0.06, ISNUMBER(MATCH($A6, CATEGORY_WEIGHTS!B$8:B$12, 0)), 0.045, ISNUMBER(MATCH($A6, CATEGORY_WEIGHTS!B$14:B$19, 0)), 0.03, ISNUMBER(MATCH($A6, CATEGORY_WEIGHTS!B$21:B$25, 0)), 0.018, ISNUMBER(MATCH($A6, CATEGORY_WEIGHTS!B$27:B$30, 0)), 0.01 ) -> 0.045 | C6: =IFS( ISNUMBER(MATCH($A6, CATEGORY_WEIGHTS!C$5:C$6, 0)), 0.06, ISNUMBER(MATCH($A6, CATEGORY_WEIGHTS!C$8:C$12, 0)), 0.045, ISNUMBER(MATCH($A6, CATEGORY_WEIGHTS!C$14:C$19, 0)), 0.03, ISNUMBER(MATCH($A6, CATEGORY_WEIGHTS!C$21:C$25, 0)), 0.018, ISNUMBER(MATCH($A6, CATEGORY_WEIGHTS!C$27:C$30, 0)), 0.01 ) -> 0.06 | D6: =IFS( ISNUMBER(MATCH($A6, CATEGORY_WEIGHTS!D$5:D$6, 0)), 0.06, ISNUMBER(MATCH($A6, CATEGORY_WEIGHTS!D$8:D$12, 0)), 0.045, ISNUMBER(MATCH($A6, CATEGORY_WEIGHTS!D$14:D$19, 0)), 0.03, ISNUMBER(MATCH($A6, CATEGORY_WEIGHTS!D$21:D$25, 0)), 0.018, ISNUMBER(MATCH($A6, CATEGORY_WEIGHTS!D$27:D$30, 0)), 0.01 ) -> 0.03 | E6: =IFS( ISNUMBER(MATCH($A6, CATEGORY_WEIGHTS!E$5:E$6, 0)), 0.06, ISNUMBER(MATCH($A6, CATEGORY_WEIGHTS!E$8:E$12, 0)), 0.045, ISNUMBER(MATCH($A6, CATEGORY_WEIGHTS!E$14:E$19, 0)), 0.03, ISNUMBER(MATCH($A6, CATEGORY_WEIGHTS!E$21:E$25, 0)), 0.018, ISNUMBER(MATCH($A6, CATEGORY_WEIGHTS!E$27:E$30, 0)), 0.01 ) -> 0.03
A7: Super Bowl MVPs | B7: =IFS( ISNUMBER(MATCH($A7, CATEGORY_WEIGHTS!B$5:B$6, 0)), 0.06, ISNUMBER(MATCH($A7, CATEGORY_WEIGHTS!B$8:B$12, 0)), 0.045, ISNUMBER(MATCH($A7, CATEGORY_WEIGHTS!B$14:B$19, 0)), 0.03, ISNUMBER(MATCH($A7, CATEGORY_WEIGHTS!B$21:B$25, 0)), 0.018, ISNUMBER(MATCH($A7, CATEGORY_WEIGHTS!B$27:B$30, 0)), 0.01 ) -> 0.03 | C7: =IFS( ISNUMBER(MATCH($A7, CATEGORY_WEIGHTS!C$5:C$6, 0)), 0.06, ISNUMBER(MATCH($A7, CATEGORY_WEIGHTS!C$8:C$12, 0)), 0.045, ISNUMBER(MATCH($A7, CATEGORY_WEIGHTS!C$14:C$19, 0)), 0.03, ISNUMBER(MATCH($A7, CATEGORY_WEIGHTS!C$21:C$25, 0)), 0.018, ISNUMBER(MATCH($A7, CATEGORY_WEIGHTS!C$27:C$30, 0)), 0.01 ) -> 0.018 | D7: =IFS( ISNUMBER(MATCH($A7, CATEGORY_WEIGHTS!D$5:D$6, 0)), 0.06, ISNUMBER(MATCH($A7, CATEGORY_WEIGHTS!D$8:D$12, 0)), 0.045, ISNUMBER(MATCH($A7, CATEGORY_WEIGHTS!D$14:D$19, 0)), 0.03, ISNUMBER(MATCH($A7, CATEGORY_WEIGHTS!D$21:D$25, 0)), 0.018, ISNUMBER(MATCH($A7, CATEGORY_WEIGHTS!D$27:D$30, 0)), 0.01 ) -> 0.03 | E7: =IFS( ISNUMBER(MATCH($A7, CATEGORY_WEIGHTS!E$5:E$6, 0)), 0.06, ISNUMBER(MATCH($A7, CATEGORY_WEIGHTS!E$8:E$12, 0)), 0.045, ISNUMBER(MATCH($A7, CATEGORY_WEIGHTS!E$14:E$19, 0)), 0.03, ISNUMBER(MATCH($A7, CATEGORY_WEIGHTS!E$21:E$25, 0)), 0.018, ISNUMBER(MATCH($A7, CATEGORY_WEIGHTS!E$27:E$30, 0)), 0.01 ) -> 0.06
A8: Playoff Success Score | B8: =IFS( ISNUMBER(MATCH($A8, CATEGORY_WEIGHTS!B$5:B$6, 0)), 0.06, ISNUMBER(MATCH($A8, CATEGORY_WEIGHTS!B$8:B$12, 0)), 0.045, ISNUMBER(MATCH($A8, CATEGORY_WEIGHTS!B$14:B$19, 0)), 0.03, ISNUMBER(MATCH($A8, CATEGORY_WEIGHTS!B$21:B$25, 0)), 0.018, ISNUMBER(MATCH($A8, CATEGORY_WEIGHTS!B$27:B$30, 0)), 0.01 ) -> 0.03 | C8: =IFS( ISNUMBER(MATCH($A8, CATEGORY_WEIGHTS!C$5:C$6, 0)), 0.06, ISNUMBER(MATCH($A8, CATEGORY_WEIGHTS!C$8:C$12, 0)), 0.045, ISNUMBER(MATCH($A8, CATEGORY_WEIGHTS!C$14:C$19, 0)), 0.03, ISNUMBER(MATCH($A8, CATEGORY_WEIGHTS!C$21:C$25, 0)), 0.018, ISNUMBER(MATCH($A8, CATEGORY_WEIGHTS!C$27:C$30, 0)), 0.01 ) -> 0.01 | D8: =IFS( ISNUMBER(MATCH($A8, CATEGORY_WEIGHTS!D$5:D$6, 0)), 0.06, ISNUMBER(MATCH($A8, CATEGORY_WEIGHTS!D$8:D$12, 0)), 0.045, ISNUMBER(MATCH($A8, CATEGORY_WEIGHTS!D$14:D$19, 0)), 0.03, ISNUMBER(MATCH($A8, CATEGORY_WEIGHTS!D$21:D$25, 0)), 0.018, ISNUMBER(MATCH($A8, CATEGORY_WEIGHTS!D$27:D$30, 0)), 0.01 ) -> 0.018 | E8: =IFS( ISNUMBER(MATCH($A8, CATEGORY_WEIGHTS!E$5:E$6, 0)), 0.06, ISNUMBER(MATCH($A8, CATEGORY_WEIGHTS!E$8:E$12, 0)), 0.045, ISNUMBER(MATCH($A8, CATEGORY_WEIGHTS!E$14:E$19, 0)), 0.03, ISNUMBER(MATCH($A8, CATEGORY_WEIGHTS!E$21:E$25, 0)), 0.018, ISNUMBER(MATCH($A8, CATEGORY_WEIGHTS!E$27:E$30, 0)), 0.01 ) -> 0.045
A9: All Pro Score | B9: =IFS( ISNUMBER(MATCH($A9, CATEGORY_WEIGHTS!B$5:B$6, 0)), 0.06, ISNUMBER(MATCH($A9, CATEGORY_WEIGHTS!B$8:B$12, 0)), 0.045, ISNUMBER(MATCH($A9, CATEGORY_WEIGHTS!B$14:B$19, 0)), 0.03, ISNUMBER(MATCH($A9, CATEGORY_WEIGHTS!B$21:B$25, 0)), 0.018, ISNUMBER(MATCH($A9, CATEGORY_WEIGHTS!B$27:B$30, 0)), 0.01 ) -> 0.03 | C9: =IFS( ISNUMBER(MATCH($A9, CATEGORY_WEIGHTS!C$5:C$6, 0)), 0.06, ISNUMBER(MATCH($A9, CATEGORY_WEIGHTS!C$8:C$12, 0)), 0.045, ISNUMBER(MATCH($A9, CATEGORY_WEIGHTS!C$14:C$19, 0)), 0.03, ISNUMBER(MATCH($A9, CATEGORY_WEIGHTS!C$21:C$25, 0)), 0.018, ISNUMBER(MATCH($A9, CATEGORY_WEIGHTS!C$27:C$30, 0)), 0.01 ) -> 0.03 | D9: =IFS( ISNUMBER(MATCH($A9, CATEGORY_WEIGHTS!D$5:D$6, 0)), 0.06, ISNUMBER(MATCH($A9, CATEGORY_WEIGHTS!D$8:D$12, 0)), 0.045, ISNUMBER(MATCH($A9, CATEGORY_WEIGHTS!D$14:D$19, 0)), 0.03, ISNUMBER(MATCH($A9, CATEGORY_WEIGHTS!D$21:D$25, 0)), 0.018, ISNUMBER(MATCH($A9, CATEGORY_WEIGHTS!D$27:D$30, 0)), 0.01 ) -> 0.03 | E9: =IFS( ISNUMBER(MATCH($A9, CATEGORY_WEIGHTS!E$5:E$6, 0)), 0.06, ISNUMBER(MATCH($A9, CATEGORY_WEIGHTS!E$8:E$12, 0)), 0.045, ISNUMBER(MATCH($A9, CATEGORY_WEIGHTS!E$14:E$19, 0)), 0.03, ISNUMBER(MATCH($A9, CATEGORY_WEIGHTS!E$21:E$25, 0)), 0.018, ISNUMBER(MATCH($A9, CATEGORY_WEIGHTS!E$27:E$30, 0)), 0.01 ) -> 0.03
A10: Playoff Elevation Score | B10: =IFS( ISNUMBER(MATCH($A10, CATEGORY_WEIGHTS!B$5:B$6, 0)), 0.06, ISNUMBER(MATCH($A10, CATEGORY_WEIGHTS!B$8:B$12, 0)), 0.045, ISNUMBER(MATCH($A10, CATEGORY_WEIGHTS!B$14:B$19, 0)), 0.03, ISNUMBER(MATCH($A10, CATEGORY_WEIGHTS!B$21:B$25, 0)), 0.018, ISNUMBER(MATCH($A10, CATEGORY_WEIGHTS!B$27:B$30, 0)), 0.01 ) -> 0.03 | C10: =IFS( ISNUMBER(MATCH($A10, CATEGORY_WEIGHTS!C$5:C$6, 0)), 0.06, ISNUMBER(MATCH($A10, CATEGORY_WEIGHTS!C$8:C$12, 0)), 0.045, ISNUMBER(MATCH($A10, CATEGORY_WEIGHTS!C$14:C$19, 0)), 0.03, ISNUMBER(MATCH($A10, CATEGORY_WEIGHTS!C$21:C$25, 0)), 0.018, ISNUMBER(MATCH($A10, CATEGORY_WEIGHTS!C$27:C$30, 0)), 0.01 ) -> 0.018 | D10: =IFS( ISNUMBER(MATCH($A10, CATEGORY_WEIGHTS!D$5:D$6, 0)), 0.06, ISNUMBER(MATCH($A10, CATEGORY_WEIGHTS!D$8:D$12, 0)), 0.045, ISNUMBER(MATCH($A10, CATEGORY_WEIGHTS!D$14:D$19, 0)), 0.03, ISNUMBER(MATCH($A10, CATEGORY_WEIGHTS!D$21:D$25, 0)), 0.018, ISNUMBER(MATCH($A10, CATEGORY_WEIGHTS!D$27:D$30, 0)), 0.01 ) -> 0.018 | E10: =IFS( ISNUMBER(MATCH($A10, CATEGORY_WEIGHTS!E$5:E$6, 0)), 0.06, ISNUMBER(MATCH($A10, CATEGORY_WEIGHTS!E$8:E$12, 0)), 0.045, ISNUMBER(MATCH($A10, CATEGORY_WEIGHTS!E$14:E$19, 0)), 0.03, ISNUMBER(MATCH($A10, CATEGORY_WEIGHTS!E$21:E$25, 0)), 0.018, ISNUMBER(MATCH($A10, CATEGORY_WEIGHTS!E$27:E$30, 0)), 0.01 ) -> 0.06
A11: Dominance Score | B11: =IFS( ISNUMBER(MATCH($A11, CATEGORY_WEIGHTS!B$5:B$6, 0)), 0.06, ISNUMBER(MATCH($A11, CATEGORY_WEIGHTS!B$8:B$12, 0)), 0.045, ISNUMBER(MATCH($A11, CATEGORY_WEIGHTS!B$14:B$19, 0)), 0.03, ISNUMBER(MATCH($A11, CATEGORY_WEIGHTS!B$21:B$25, 0)), 0.018, ISNUMBER(MATCH($A11, CATEGORY_WEIGHTS!B$27:B$30, 0)), 0.01 ) -> 0.03 | C11: =IFS( ISNUMBER(MATCH($A11, CATEGORY_WEIGHTS!C$5:C$6, 0)), 0.06, ISNUMBER(MATCH($A11, CATEGORY_WEIGHTS!C$8:C$12, 0)), 0.045, ISNUMBER(MATCH($A11, CATEGORY_WEIGHTS!C$14:C$19, 0)), 0.03, ISNUMBER(MATCH($A11, CATEGORY_WEIGHTS!C$21:C$25, 0)), 0.018, ISNUMBER(MATCH($A11, CATEGORY_WEIGHTS!C$27:C$30, 0)), 0.01 ) -> 0.045 | D11: =IFS( ISNUMBER(MATCH($A11, CATEGORY_WEIGHTS!D$5:D$6, 0)), 0.06, ISNUMBER(MATCH($A11, CATEGORY_WEIGHTS!D$8:D$12, 0)), 0.045, ISNUMBER(MATCH($A11, CATEGORY_WEIGHTS!D$14:D$19, 0)), 0.03, ISNUMBER(MATCH($A11, CATEGORY_WEIGHTS!D$21:D$25, 0)), 0.018, ISNUMBER(MATCH($A11, CATEGORY_WEIGHTS!D$27:D$30, 0)), 0.01 ) -> 0.06 | E11: =IFS( ISNUMBER(MATCH($A11, CATEGORY_WEIGHTS!E$5:E$6, 0)), 0.06, ISNUMBER(MATCH($A11, CATEGORY_WEIGHTS!E$8:E$12, 0)), 0.045, ISNUMBER(MATCH($A11, CATEGORY_WEIGHTS!E$14:E$19, 0)), 0.03, ISNUMBER(MATCH($A11, CATEGORY_WEIGHTS!E$21:E$25, 0)), 0.018, ISNUMBER(MATCH($A11, CATEGORY_WEIGHTS!E$27:E$30, 0)), 0.01 ) -> 0.03
A12: Career ANY/A+ | B12: =IFS( ISNUMBER(MATCH($A12, CATEGORY_WEIGHTS!B$5:B$6, 0)), 0.06, ISNUMBER(MATCH($A12, CATEGORY_WEIGHTS!B$8:B$12, 0)), 0.045, ISNUMBER(MATCH($A12, CATEGORY_WEIGHTS!B$14:B$19, 0)), 0.03, ISNUMBER(MATCH($A12, CATEGORY_WEIGHTS!B$21:B$25, 0)), 0.018, ISNUMBER(MATCH($A12, CATEGORY_WEIGHTS!B$27:B$30, 0)), 0.01 ) -> 0.018 | C12: =IFS( ISNUMBER(MATCH($A12, CATEGORY_WEIGHTS!C$5:C$6, 0)), 0.06, ISNUMBER(MATCH($A12, CATEGORY_WEIGHTS!C$8:C$12, 0)), 0.045, ISNUMBER(MATCH($A12, CATEGORY_WEIGHTS!C$14:C$19, 0)), 0.03, ISNUMBER(MATCH($A12, CATEGORY_WEIGHTS!C$21:C$25, 0)), 0.018, ISNUMBER(MATCH($A12, CATEGORY_WEIGHTS!C$27:C$30, 0)), 0.01 ) -> 0.045 | D12: =IFS( ISNUMBER(MATCH($A12, CATEGORY_WEIGHTS!D$5:D$6, 0)), 0.06, ISNUMBER(MATCH($A12, CATEGORY_WEIGHTS!D$8:D$12, 0)), 0.045, ISNUMBER(MATCH($A12, CATEGORY_WEIGHTS!D$14:D$19, 0)), 0.03, ISNUMBER(MATCH($A12, CATEGORY_WEIGHTS!D$21:D$25, 0)), 0.018, ISNUMBER(MATCH($A12, CATEGORY_WEIGHTS!D$27:D$30, 0)), 0.01 ) -> 0.045 | E12: =IFS( ISNUMBER(MATCH($A12, CATEGORY_WEIGHTS!E$5:E$6, 0)), 0.06, ISNUMBER(MATCH($A12, CATEGORY_WEIGHTS!E$8:E$12, 0)), 0.045, ISNUMBER(MATCH($A12, CATEGORY_WEIGHTS!E$14:E$19, 0)), 0.03, ISNUMBER(MATCH($A12, CATEGORY_WEIGHTS!E$21:E$25, 0)), 0.018, ISNUMBER(MATCH($A12, CATEGORY_WEIGHTS!E$27:E$30, 0)), 0.01 ) -> 0.018
A13: Negative Play Rate | B13: =IFS( ISNUMBER(MATCH($A13, CATEGORY_WEIGHTS!B$5:B$6, 0)), 0.06, ISNUMBER(MATCH($A13, CATEGORY_WEIGHTS!B$8:B$12, 0)), 0.045, ISNUMBER(MATCH($A13, CATEGORY_WEIGHTS!B$14:B$19, 0)), 0.03, ISNUMBER(MATCH($A13, CATEGORY_WEIGHTS!B$21:B$25, 0)), 0.018, ISNUMBER(MATCH($A13, CATEGORY_WEIGHTS!B$27:B$30, 0)), 0.01 ) -> 0.018 | C13: =IFS( ISNUMBER(MATCH($A13, CATEGORY_WEIGHTS!C$5:C$6, 0)), 0.06, ISNUMBER(MATCH($A13, CATEGORY_WEIGHTS!C$8:C$12, 0)), 0.045, ISNUMBER(MATCH($A13, CATEGORY_WEIGHTS!C$14:C$19, 0)), 0.03, ISNUMBER(MATCH($A13, CATEGORY_WEIGHTS!C$21:C$25, 0)), 0.018, ISNUMBER(MATCH($A13, CATEGORY_WEIGHTS!C$27:C$30, 0)), 0.01 ) -> 0.03 | D13: =IFS( ISNUMBER(MATCH($A13, CATEGORY_WEIGHTS!D$5:D$6, 0)), 0.06, ISNUMBER(MATCH($A13, CATEGORY_WEIGHTS!D$8:D$12, 0)), 0.045, ISNUMBER(MATCH($A13, CATEGORY_WEIGHTS!D$14:D$19, 0)), 0.03, ISNUMBER(MATCH($A13, CATEGORY_WEIGHTS!D$21:D$25, 0)), 0.018, ISNUMBER(MATCH($A13, CATEGORY_WEIGHTS!D$27:D$30, 0)), 0.01 ) -> 0.018 | E13: =IFS( ISNUMBER(MATCH($A13, CATEGORY_WEIGHTS!E$5:E$6, 0)), 0.06, ISNUMBER(MATCH($A13, CATEGORY_WEIGHTS!E$8:E$12, 0)), 0.045, ISNUMBER(MATCH($A13, CATEGORY_WEIGHTS!E$14:E$19, 0)), 0.03, ISNUMBER(MATCH($A13, CATEGORY_WEIGHTS!E$21:E$25, 0)), 0.018, ISNUMBER(MATCH($A13, CATEGORY_WEIGHTS!E$27:E$30, 0)), 0.01 ) -> 0.018
A14: Pro Bowls | B14: =IFS( ISNUMBER(MATCH($A14, CATEGORY_WEIGHTS!B$5:B$6, 0)), 0.06, ISNUMBER(MATCH($A14, CATEGORY_WEIGHTS!B$8:B$12, 0)), 0.045, ISNUMBER(MATCH($A14, CATEGORY_WEIGHTS!B$14:B$19, 0)), 0.03, ISNUMBER(MATCH($A14, CATEGORY_WEIGHTS!B$21:B$25, 0)), 0.018, ISNUMBER(MATCH($A14, CATEGORY_WEIGHTS!B$27:B$30, 0)), 0.01 ) -> 0.01 | C14: =IFS( ISNUMBER(MATCH($A14, CATEGORY_WEIGHTS!C$5:C$6, 0)), 0.06, ISNUMBER(MATCH($A14, CATEGORY_WEIGHTS!C$8:C$12, 0)), 0.045, ISNUMBER(MATCH($A14, CATEGORY_WEIGHTS!C$14:C$19, 0)), 0.03, ISNUMBER(MATCH($A14, CATEGORY_WEIGHTS!C$21:C$25, 0)), 0.018, ISNUMBER(MATCH($A14, CATEGORY_WEIGHTS!C$27:C$30, 0)), 0.01 ) -> 0.01 | D14: =IFS( ISNUMBER(MATCH($A14, CATEGORY_WEIGHTS!D$5:D$6, 0)), 0.06, ISNUMBER(MATCH($A14, CATEGORY_WEIGHTS!D$8:D$12, 0)), 0.045, ISNUMBER(MATCH($A14, CATEGORY_WEIGHTS!D$14:D$19, 0)), 0.03, ISNUMBER(MATCH($A14, CATEGORY_WEIGHTS!D$21:D$25, 0)), 0.018, ISNUMBER(MATCH($A14, CATEGORY_WEIGHTS!D$27:D$30, 0)), 0.01 ) -> 0.01 | E14: =IFS( ISNUMBER(MATCH($A14, CATEGORY_WEIGHTS!E$5:E$6, 0)), 0.06, ISNUMBER(MATCH($A14, CATEGORY_WEIGHTS!E$8:E$12, 0)), 0.045, ISNUMBER(MATCH($A14, CATEGORY_WEIGHTS!E$14:E$19, 0)), 0.03, ISNUMBER(MATCH($A14, CATEGORY_WEIGHTS!E$21:E$25, 0)), 0.018, ISNUMBER(MATCH($A14, CATEGORY_WEIGHTS!E$27:E$30, 0)), 0.01 ) -> 0.01
A15: Rush Yards per Game | B15: =IFS( ISNUMBER(MATCH($A15, CATEGORY_WEIGHTS!B$5:B$6, 0)), 0.06, ISNUMBER(MATCH($A15, CATEGORY_WEIGHTS!B$8:B$12, 0)), 0.045, ISNUMBER(MATCH($A15, CATEGORY_WEIGHTS!B$14:B$19, 0)), 0.03, ISNUMBER(MATCH($A15, CATEGORY_WEIGHTS!B$21:B$25, 0)), 0.018, ISNUMBER(MATCH($A15, CATEGORY_WEIGHTS!B$27:B$30, 0)), 0.01 ) -> 0.01 | C15: =IFS( ISNUMBER(MATCH($A15, CATEGORY_WEIGHTS!C$5:C$6, 0)), 0.06, ISNUMBER(MATCH($A15, CATEGORY_WEIGHTS!C$8:C$12, 0)), 0.045, ISNUMBER(MATCH($A15, CATEGORY_WEIGHTS!C$14:C$19, 0)), 0.03, ISNUMBER(MATCH($A15, CATEGORY_WEIGHTS!C$21:C$25, 0)), 0.018, ISNUMBER(MATCH($A15, CATEGORY_WEIGHTS!C$27:C$30, 0)), 0.01 ) -> 0.018 | D15: =IFS( ISNUMBER(MATCH($A15, CATEGORY_WEIGHTS!D$5:D$6, 0)), 0.06, ISNUMBER(MATCH($A15, CATEGORY_WEIGHTS!D$8:D$12, 0)), 0.045, ISNUMBER(MATCH($A15, CATEGORY_WEIGHTS!D$14:D$19, 0)), 0.03, ISNUMBER(MATCH($A15, CATEGORY_WEIGHTS!D$21:D$25, 0)), 0.018, ISNUMBER(MATCH($A15, CATEGORY_WEIGHTS!D$27:D$30, 0)), 0.01 ) -> 0.01 | E15: =IFS( ISNUMBER(MATCH($A15, CATEGORY_WEIGHTS!E$5:E$6, 0)), 0.06, ISNUMBER(MATCH($A15, CATEGORY_WEIGHTS!E$8:E$12, 0)), 0.045, ISNUMBER(MATCH($A15, CATEGORY_WEIGHTS!E$14:E$19, 0)), 0.03, ISNUMBER(MATCH($A15, CATEGORY_WEIGHTS!E$21:E$25, 0)), 0.018, ISNUMBER(MATCH($A15, CATEGORY_WEIGHTS!E$27:E$30, 0)), 0.01 ) -> 0.01
A16: MODEL SUM | B16: =SUM(Weights_by_Category[GREATEST]) -> 0.446 | C16: =sum(Weights_by_Category[BEST]) -> 0.399 | D16: =sum(Weights_by_Category[DOMINANT]) -> 0.419 | E16: =SUM(Weights_by_Category[CLUTCH]) -> 0.464

Sheet MODEL_GREATEST
A1: # | B1: QB | C1: GREATNESS SCORE | D1: Super Bowls | E1: Playoff Success Score | F1: Super Bowl MVPs | G1: MVP Shares | H1: All-Pro Score | I1: Pro Bowls | J1: Career Passing Yards | K1: Career Passing Touchdowns | L1: Career ANY/A+ | M1: Rush Yards per Game | N1: Negative Play Rate | O1: Peak Score | P1: Dominance Score | Q1: Playoff Elevation Score | R1: TOTAL
A2: 1 | B2: Tom Brady | C2: =R2/Weights_by_Category[[#TOTALS],[GREATEST]] -> 81.943889 | D2: =NORMALIZED_DATA!B2*TIER_WEIGHTS!$B$2 -> 6 | E2: =NORMALIZED_DATA!C2*TIER_WEIGHTS!$B$8 -> 3 | F2: =NORMALIZED_DATA!D2*TIER_WEIGHTS!$B$7 -> 3 | G2: =NORMALIZED_DATA!F2*TIER_WEIGHTS!$B$3 -> 3.5371179 | H2: =NORMALIZED_DATA!G2*TIER_WEIGHTS!$B$9 -> 1.5882353 | I2: =NORMALIZED_DATA!H2*TIER_WEIGHTS!$B$14 -> 1 | J2: =NORMALIZED_DATA!I2*TIER_WEIGHTS!$B$4 -> 4.5 | K2: =NORMALIZED_DATA!N2*TIER_WEIGHTS!$B$5 -> 4.5 | L2: =NORMALIZED_DATA!U2*TIER_WEIGHTS!$B$12 -> 0.96923077 | M2: =NORMALIZED_DATA!V2*TIER_WEIGHTS!$B$15 -> 0.053545845 | N2: =NORMALIZED_DATA!W2*TIER_WEIGHTS!$B$13 -> 1.773913 | O2: =NORMALIZED_DATA!Y2*TIER_WEIGHTS!$B$6 -> 3.2544643 | P2: =NORMALIZED_DATA!Z2*TIER_WEIGHTS!$B$11 -> 1.6666667 | Q2: =NORMALIZED_DATA!AA2*TIER_WEIGHTS!$B$10 -> 1.7038006 | R2: =sum(D2:Q2) -> 36.546974
A3: 2 | B3: Peyton Manning | C3: =R3/Weights_by_Category[[#TOTALS],[GREATEST]] -> 66.817976 | D3: =NORMALIZED_DATA!B4*TIER_WEIGHTS!$B$2 -> 1.7142857 | E3: =NORMALIZED_DATA!C4*TIER_WEIGHTS!$B$8 -> 1.2083333 | F3: =NORMALIZED_DATA!D4*TIER_WEIGHTS!$B$7 -> 0.6 | G3: =NORMALIZED_DATA!F4*TIER_WEIGHTS!$B$3 -> 4.5 | H3: =NORMALIZED_DATA!G4*TIER_WEIGHTS!$B$9 -> 3 | I3: =NORMALIZED_DATA!H4*TIER_WEIGHTS!$B$14 -> 0.91666667 | J3: =NORMALIZED_DATA!I4*TIER_WEIGHTS!$B$4 -> 3.3454581 | K3: =NORMALIZED_DATA!N4*TIER_WEIGHTS!$B$5 -> 3.5040241 | L3: =NORMALIZED_DATA!U4*TIER_WEIGHTS!$B$12 -> 1.2461538 | M3: =NORMALIZED_DATA!V4*TIER_WEIGHTS!$B$15 -> 0.038502865 | N3: =NORMALIZED_DATA!W4*TIER_WEIGHTS!$B$13 -> 1.4347826 | O3: =NORMALIZED_DATA!Y4*TIER_WEIGHTS!$B$6 -> 4.0178571 | P3: =NORMALIZED_DATA!Z4*TIER_WEIGHTS!$B$11 -> 2.6666667 | Q3: =NORMALIZED_DATA!AA4*TIER_WEIGHTS!$B$10 -> 1.6080862 | R3: =sum(D3:Q3) -> 29.800817
A4: 3 | B4: Aaron Rodgers | C4: =R4/Weights_by_Category[[#TOTALS],[GREATEST]] -> 52.882056 | D4: =NORMALIZED_DATA!B7*TIER_WEIGHTS!$B$2 -> 0.85714286 | E4: =NORMALIZED_DATA!C7*TIER_WEIGHTS!$B$8 -> 0.83333333 | F4: =NORMALIZED_DATA!D7*TIER_WEIGHTS!$B$7 -> 0.6 | G4: =NORMALIZED_DATA!F7*TIER_WEIGHTS!$B$3 -> 3.2227074 | H4: =NORMALIZED_DATA!G7*TIER_WEIGHTS!$B$9 -> 1.5882353 | I4: =NORMALIZED_DATA!H7*TIER_WEIGHTS!$B$14 -> 0.58333333 | J4: =NORMALIZED_DATA!I7*TIER_WEIGHTS!$B$4 -> 2.9667597 | K4: =NORMALIZED_DATA!N7*TIER_WEIGHTS!$B$5 -> 3.3953722 | L4: =NORMALIZED_DATA!U7*TIER_WEIGHTS!$B$12 -> 0.9 | M4: =NORMALIZED_DATA!V7*TIER_WEIGHTS!$B$15 -> 0.24068768 | N4: =NORMALIZED_DATA!W7*TIER_WEIGHTS!$B$13 -> 1.4869565 | O4: =NORMALIZED_DATA!Y7*TIER_WEIGHTS!$B$6 -> 3.4151786 | P4: =NORMALIZED_DATA!Z7*TIER_WEIGHTS!$B$11 -> 1.6666667 | Q4: =NORMALIZED_DATA!AA7*TIER_WEIGHTS!$B$10 -> 1.8290233 | R4: =sum(D4:Q4) -> 23.585397
A5: 4 | B5: Otto Graham | C5: =R5/Weights_by_Category[[#TOTALS],[GREATEST]] -> 49.757899 | D5: =NORMALIZED_DATA!B16*TIER_WEIGHTS!$B$2 -> 6 | E5: =NORMALIZED_DATA!C16*TIER_WEIGHTS!$B$8 -> 0.33333333 | F5: =NORMALIZED_DATA!D16*TIER_WEIGHTS!$B$7 -> 0 | G5: =NORMALIZED_DATA!F16*TIER_WEIGHTS!$B$3 -> 2.0731441 | H5: =NORMALIZED_DATA!G16*TIER_WEIGHTS!$B$9 -> 1.7647059 | I5: =NORMALIZED_DATA!H16*TIER_WEIGHTS!$B$14 -> 0.16666667 | J5: =NORMALIZED_DATA!I16*TIER_WEIGHTS!$B$4 -> 0.11348919 | K5: =NORMALIZED_DATA!N16*TIER_WEIGHTS!$B$5 -> 0.19919517 | L5: =NORMALIZED_DATA!U16*TIER_WEIGHTS!$B$12 -> 1.8 | M5: =NORMALIZED_DATA!V16*TIER_WEIGHTS!$B$15 -> 0.11891117 | N5: =NORMALIZED_DATA!W16*TIER_WEIGHTS!$B$13 -> 1.773913 | O5: =NORMALIZED_DATA!Y16*TIER_WEIGHTS!$B$6 -> 4.1785714 | P5: =NORMALIZED_DATA!Z16*TIER_WEIGHTS!$B$11 -> 2.6666667 | Q5: =NORMALIZED_DATA!AA16*TIER_WEIGHTS!$B$10 -> 1.0034263 | R5: =sum(D5:Q5) -> 22.192023
A6: 5 | B6: Joe Montana | C6: =R6/Weights_by_Category[[#TOTALS],[GREATEST]] -> 46.853122 | D6: =NORMALIZED_DATA!B3*TIER_WEIGHTS!$B$2 -> 3.4285714 | E6: =NORMALIZED_DATA!C3*TIER_WEIGHTS!$B$8 -> 1.2916667 | F6: =NORMALIZED_DATA!D3*TIER_WEIGHTS!$B$7 -> 1.8 | G6: =NORMALIZED_DATA!F3*TIER_WEIGHTS!$B$3 -> 1.6015284 | H6: =NORMALIZED_DATA!G3*TIER_WEIGHTS!$B$9 -> 1.4117647 | I6: =NORMALIZED_DATA!H3*TIER_WEIGHTS!$B$14 -> 0.41666667 | J6: =NORMALIZED_DATA!I3*TIER_WEIGHTS!$B$4 -> 1.2475122 | K6: =NORMALIZED_DATA!N3*TIER_WEIGHTS!$B$5 -> 1.0955734 | L6: =NORMALIZED_DATA!U3*TIER_WEIGHTS!$B$12 -> 1.2461538 | M6: =NORMALIZED_DATA!V3*TIER_WEIGHTS!$B$15 -> 0.14989255 | N6: =NORMALIZED_DATA!W3*TIER_WEIGHTS!$B$13 -> 1.7217391 | O6: =NORMALIZED_DATA!Y3*TIER_WEIGHTS!$B$6 -> 2.3303571 | P6: =NORMALIZED_DATA!Z3*TIER_WEIGHTS!$B$11 -> 1 | Q6: =NORMALIZED_DATA!AA3*TIER_WEIGHTS!$B$10 -> 2.1550662 | R6: =sum(D6:Q6) -> 20.896492
A7: 6 | B7: Drew Brees | C7: =R7/Weights_by_Category[[#TOTALS],[GREATEST]] -> 46.630254 | D7: =NORMALIZED_DATA!B5*TIER_WEIGHTS!$B$2 -> 0.85714286 | E7: =NORMALIZED_DATA!C5*TIER_WEIGHTS!$B$8 -> 0.58333333 | F7: =NORMALIZED_DATA!D5*TIER_WEIGHTS!$B$7 -> 0.6 | G7: =NORMALIZED_DATA!F5*TIER_WEIGHTS!$B$3 -> 0.44213974 | H7: =NORMALIZED_DATA!G5*TIER_WEIGHTS!$B$9 -> 1.0588235 | I7: =NORMALIZED_DATA!H5*TIER_WEIGHTS!$B$14 -> 0.83333333 | J7: =NORMALIZED_DATA!I5*TIER_WEIGHTS!$B$4 -> 3.9080917 | K7: =NORMALIZED_DATA!N5*TIER_WEIGHTS!$B$5 -> 3.7937626 | L7: =NORMALIZED_DATA!U5*TIER_WEIGHTS!$B$12 -> 0.96923077 | M7: =NORMALIZED_DATA!V5*TIER_WEIGHTS!$B$15 -> 0.040472779 | N7: =NORMALIZED_DATA!W5*TIER_WEIGHTS!$B$13 -> 1.4086957 | O7: =NORMALIZED_DATA!Y5*TIER_WEIGHTS!$B$6 -> 2.0491071 | P7: =NORMALIZED_DATA!Z5*TIER_WEIGHTS!$B$11 -> 2.3333333 | Q7: =NORMALIZED_DATA!AA5*TIER_WEIGHTS!$B$10 -> 1.9196265 | R7: =sum(D7:Q7) -> 20.797093
A8: 7 | B8: Patrick Mahomes | C8: =R8/Weights_by_Category[[#TOTALS],[GREATEST]] -> 44.492196 | D8: =NORMALIZED_DATA!B9*TIER_WEIGHTS!$B$2 -> 2.5714286 | E8: =NORMALIZED_DATA!C9*TIER_WEIGHTS!$B$8 -> 1.5 | F8: =NORMALIZED_DATA!D9*TIER_WEIGHTS!$B$7 -> 1.8 | G8: =NORMALIZED_DATA!F9*TIER_WEIGHTS!$B$3 -> 1.8962882 | H8: =NORMALIZED_DATA!G9*TIER_WEIGHTS!$B$9 -> 0.88235294 | I8: =NORMALIZED_DATA!H9*TIER_WEIGHTS!$B$14 -> 0.25 | J8: =NORMALIZED_DATA!I9*TIER_WEIGHTS!$B$4 -> 0.93926004 | K8: =NORMALIZED_DATA!N9*TIER_WEIGHTS!$B$5 -> 1.0412475 | L8: =NORMALIZED_DATA!U9*TIER_WEIGHTS!$B$12 -> 1.0384615 | M8: =NORMALIZED_DATA!V9*TIER_WEIGHTS!$B$15 -> 0.37320917 | N8: =NORMALIZED_DATA!W9*TIER_WEIGHTS!$B$13 -> 1.3826087 | O8: =NORMALIZED_DATA!Y9*TIER_WEIGHTS!$B$6 -> 2.8125 | P8: =NORMALIZED_DATA!Z9*TIER_WEIGHTS!$B$11 -> 1.3333333 | Q8: =NORMALIZED_DATA!AA9*TIER_WEIGHTS!$B$10 -> 2.0228294 | R8: =sum(D8:Q8) -> 19.843519
A9: 8 | B9: Brett Favre | C9: =R9/Weights_by_Category[[#TOTALS],[GREATEST]] -> 42.772917 | D9: =NORMALIZED_DATA!B17*TIER_WEIGHTS!$B$2 -> 0.85714286 | E9: =NORMALIZED_DATA!C17*TIER_WEIGHTS!$B$8 -> 0.95833333 | F9: =NORMALIZED_DATA!D17*TIER_WEIGHTS!$B$7 -> 0 | G9: =NORMALIZED_DATA!F17*TIER_WEIGHTS!$B$3 -> 2.1320961 | H9: =NORMALIZED_DATA!G17*TIER_WEIGHTS!$B$9 -> 1.5882353 | I9: =NORMALIZED_DATA!H17*TIER_WEIGHTS!$B$14 -> 0.66666667 | J9: =NORMALIZED_DATA!I17*TIER_WEIGHTS!$B$4 -> 3.3386407 | K9: =NORMALIZED_DATA!N17*TIER_WEIGHTS!$B$5 -> 3.22334 | L9: =NORMALIZED_DATA!U17*TIER_WEIGHTS!$B$12 -> 0.41538462 | M9: =NORMALIZED_DATA!V17*TIER_WEIGHTS!$B$15 -> 0.10297278 | N9: =NORMALIZED_DATA!W17*TIER_WEIGHTS!$B$13 -> 0.75652174 | O9: =NORMALIZED_DATA!Y17*TIER_WEIGHTS!$B$6 -> 1.2455357 | P9: =NORMALIZED_DATA!Z17*TIER_WEIGHTS!$B$11 -> 1.6666667 | Q9: =NORMALIZED_DATA!AA17*TIER_WEIGHTS!$B$10 -> 2.1251847 | R9: =sum(D9:Q9) -> 19.076721
A10: 9 | B10: Steve Young | C10: =R10/Weights_by_Category[[#TOTALS],[GREATEST]] -> 42.204584 | D10: =NORMALIZED_DATA!B13*TIER_WEIGHTS!$B$2 -> 0.85714286 | E10: =NORMALIZED_DATA!C13*TIER_WEIGHTS!$B$8 -> 1.1666667 | F10: =NORMALIZED_DATA!D13*TIER_WEIGHTS!$B$7 -> 0.6 | G10: =NORMALIZED_DATA!F13*TIER_WEIGHTS!$B$3 -> 1.7489083 | H10: =NORMALIZED_DATA!G13*TIER_WEIGHTS!$B$9 -> 1.5882353 | I10: =NORMALIZED_DATA!H13*TIER_WEIGHTS!$B$14 -> 0.33333333 | J10: =NORMALIZED_DATA!I13*TIER_WEIGHTS!$B$4 -> 0.75111395 | K10: =NORMALIZED_DATA!N13*TIER_WEIGHTS!$B$5 -> 0.72434608 | L10: =NORMALIZED_DATA!U13*TIER_WEIGHTS!$B$12 -> 1.3846154 | M10: =NORMALIZED_DATA!V13*TIER_WEIGHTS!$B$15 -> 0.44305158 | N10: =NORMALIZED_DATA!W13*TIER_WEIGHTS!$B$13 -> 1.0956522 | O10: =NORMALIZED_DATA!Y13*TIER_WEIGHTS!$B$6 -> 4.5 | P10: =NORMALIZED_DATA!Z13*TIER_WEIGHTS!$B$11 -> 2 | Q10: =NORMALIZED_DATA!AA13*TIER_WEIGHTS!$B$10 -> 1.6301789 | R10: =sum(D10:Q10) -> 18.823244
A11: 10 | B11: Dan Marino | C11: =R11/Weights_by_Category[[#TOTALS],[GREATEST]] -> 41.47069 | D11: =NORMALIZED_DATA!B10*TIER_WEIGHTS!$B$2 -> 0 | E11: =NORMALIZED_DATA!C10*TIER_WEIGHTS!$B$8 -> 0.58333333 | F11: =NORMALIZED_DATA!D10*TIER_WEIGHTS!$B$7 -> 0 | G11: =NORMALIZED_DATA!F10*TIER_WEIGHTS!$B$3 -> 0.75655022 | H11: =NORMALIZED_DATA!G10*TIER_WEIGHTS!$B$9 -> 1.5882353 | I11: =NORMALIZED_DATA!H10*TIER_WEIGHTS!$B$14 -> 0.5 | J11: =NORMALIZED_DATA!I10*TIER_WEIGHTS!$B$4 -> 2.6383897 | K11: =NORMALIZED_DATA!N10*TIER_WEIGHTS!$B$5 -> 2.4265594 | L11: =NORMALIZED_DATA!U10*TIER_WEIGHTS!$B$12 -> 1.1769231 | M11: =NORMALIZED_DATA!V10*TIER_WEIGHTS!$B$15 -> 0 | N11: =NORMALIZED_DATA!W10*TIER_WEIGHTS!$B$13 -> 1.6956522 | O11: =NORMALIZED_DATA!Y10*TIER_WEIGHTS!$B$6 -> 3.6160714 | P11: =NORMALIZED_DATA!Z10*TIER_WEIGHTS!$B$11 -> 2 | Q11: =NORMALIZED_DATA!AA10*TIER_WEIGHTS!$B$10 -> 1.5142132 | R11: =sum(D11:Q11) -> 18.495928
A12: 11 | B12: Johnny Unitas | C12: =R12/Weights_by_Category[[#TOTALS],[GREATEST]] -> 37.796774 | D12: =NORMALIZED_DATA!B8*TIER_WEIGHTS!$B$2 -> 2.5714286 | E12: =NORMALIZED_DATA!C8*TIER_WEIGHTS!$B$8 -> 0.33333333 | F12: =NORMALIZED_DATA!D8*TIER_WEIGHTS!$B$7 -> 0 | G12: =NORMALIZED_DATA!F8*TIER_WEIGHTS!$B$3 -> 2.7412664 | H12: =NORMALIZED_DATA!G8*TIER_WEIGHTS!$B$9 -> 2.2941176 | I12: =NORMALIZED_DATA!H8*TIER_WEIGHTS!$B$14 -> 0.58333333 | J12: =NORMALIZED_DATA!I8*TIER_WEIGHTS!$B$4 -> 1.226659 | K12: =NORMALIZED_DATA!N8*TIER_WEIGHTS!$B$5 -> 1.249497 | L12: =NORMALIZED_DATA!U8*TIER_WEIGHTS!$B$12 -> 0.34615385 | M12: =NORMALIZED_DATA!V8*TIER_WEIGHTS!$B$15 -> 0.14434097 | N12: =NORMALIZED_DATA!W8*TIER_WEIGHTS!$B$13 -> 1.0513043 | O12: =NORMALIZED_DATA!Y8*TIER_WEIGHTS!$B$6 -> 1.7678571 | P12: =NORMALIZED_DATA!Z8*TIER_WEIGHTS!$B$11 -> 1.3333333 | Q12: =NORMALIZED_DATA!AA8*TIER_WEIGHTS!$B$10 -> 1.2147362 | R12: =sum(D12:Q12) -> 16.857361
A13: 12 | B13: Sammy Baugh | C13: =R13/Weights_by_Category[[#TOTALS],[GREATEST]] -> 35.33223 | D13: =NORMALIZED_DATA!B23*TIER_WEIGHTS!$B$2 -> 1.7142857 | E13: =NORMALIZED_DATA!C23*TIER_WEIGHTS!$B$8 -> 0.16666667 | F13: =NORMALIZED_DATA!D23*TIER_WEIGHTS!$B$7 -> 0 | G13: =NORMALIZED_DATA!F23*TIER_WEIGHTS!$B$3 -> 0 | H13: =NORMALIZED_DATA!G23*TIER_WEIGHTS!$B$9 -> 2.1176471 | I13: =NORMALIZED_DATA!H23*TIER_WEIGHTS!$B$14 -> 0.25 | J13: =NORMALIZED_DATA!I23*TIER_WEIGHTS!$B$4 -> 0 | K13: =NORMALIZED_DATA!N23*TIER_WEIGHTS!$B$5 -> 0.31690141 | L13: =NORMALIZED_DATA!U23*TIER_WEIGHTS!$B$12 -> 1.1769231 | M13: =NORMALIZED_DATA!V23*TIER_WEIGHTS!$B$15 -> 0.028474212 | N13: =NORMALIZED_DATA!W23*TIER_WEIGHTS!$B$13 -> 1.8 | O13: =NORMALIZED_DATA!Y23*TIER_WEIGHTS!$B$6 -> 2.953125 | P13: =NORMALIZED_DATA!Z23*TIER_WEIGHTS!$B$11 -> 3 | Q13: =NORMALIZED_DATA!AA23*TIER_WEIGHTS!$B$10 -> 2.2341516 | R13: =sum(D13:Q13) -> 15.758175
A14: 13 | B14: Bart Starr | C14: =R14/Weights_by_Category[[#TOTALS],[GREATEST]] -> 31.834058 | D14: =NORMALIZED_DATA!B6*TIER_WEIGHTS!$B$2 -> 4.2857143 | E14: =NORMALIZED_DATA!C6*TIER_WEIGHTS!$B$8 -> 0.58333333 | F14: =NORMALIZED_DATA!D6*TIER_WEIGHTS!$B$7 -> 1.2 | G14: =NORMALIZED_DATA!F6*TIER_WEIGHTS!$B$3 -> 0.41266376 | H14: =NORMALIZED_DATA!G6*TIER_WEIGHTS!$B$9 -> 0.88235294 | I14: =NORMALIZED_DATA!H6*TIER_WEIGHTS!$B$14 -> 0.083333333 | J14: =NORMALIZED_DATA!I6*TIER_WEIGHTS!$B$4 -> 0.18928232 | K14: =NORMALIZED_DATA!N6*TIER_WEIGHTS!$B$5 -> 0 | L14: =NORMALIZED_DATA!U6*TIER_WEIGHTS!$B$12 -> 0.62307692 | M14: =NORMALIZED_DATA!V6*TIER_WEIGHTS!$B$15 -> 0.11300143 | N14: =NORMALIZED_DATA!W6*TIER_WEIGHTS!$B$13 -> 0.76304348 | O14: =NORMALIZED_DATA!Y6*TIER_WEIGHTS!$B$6 -> 1.2857143 | P14: =NORMALIZED_DATA!Z6*TIER_WEIGHTS!$B$11 -> 1 | Q14: =NORMALIZED_DATA!AA6*TIER_WEIGHTS!$B$10 -> 2.7764738 | R14: =sum(D14:Q14) -> 14.19799
A15: 14 | B15: Dan Fouts | C15: =R15/Weights_by_Category[[#TOTALS],[GREATEST]] -> 31.570568 | D15: =NORMALIZED_DATA!B20*TIER_WEIGHTS!$B$2 -> 0 | E15: =NORMALIZED_DATA!C20*TIER_WEIGHTS!$B$8 -> 0.20833333 | F15: =NORMALIZED_DATA!D20*TIER_WEIGHTS!$B$7 -> 0 | G15: =NORMALIZED_DATA!F20*TIER_WEIGHTS!$B$3 -> 0.74672489 | H15: =NORMALIZED_DATA!G20*TIER_WEIGHTS!$B$9 -> 1.0588235 | I15: =NORMALIZED_DATA!H20*TIER_WEIGHTS!$B$14 -> 0.25 | J15: =NORMALIZED_DATA!I20*TIER_WEIGHTS!$B$4 -> 1.4138694 | K15: =NORMALIZED_DATA!N20*TIER_WEIGHTS!$B$5 -> 0.92354125 | L15: =NORMALIZED_DATA!U20*TIER_WEIGHTS!$B$12 -> 1.0384615 | M15: =NORMALIZED_DATA!V20*TIER_WEIGHTS!$B$15 -> 0.040651862 | N15: =NORMALIZED_DATA!W20*TIER_WEIGHTS!$B$13 -> 1.1217391 | O15: =NORMALIZED_DATA!Y20*TIER_WEIGHTS!$B$6 -> 3.3348214 | P15: =NORMALIZED_DATA!Z20*TIER_WEIGHTS!$B$11 -> 2.3333333 | Q15: =NORMALIZED_DATA!AA20*TIER_WEIGHTS!$B$10 -> 1.6101737 | R15: =sum(D15:Q15) -> 14.080473
